Workbook

Sheet 251007
A1: id | B1: Q_SurveyFinished | C1: Q_RecordedDate | D1: Q_Consent | E1: Q_PlayerNumber | F1: Q_Experience | G1: Q_Experiencecode | H1: Q_Info_G$overnment | I1: Q_Info_G$overnmentcode | J1: Q_Info_WeatherForecast | K1: Q_Info_WeatherForecastcode | L1: Q_Info_Scientific | M1: Q_Info_Scientificcode | N1: Q_Info_G$eneralMedia | O1: Q_Info_G$eneralMediacode | P1: Q_Info_SocialMedia | Q1: Q_Info_SocialMediacode | R1: Q_Info_EnG$ineerinG$ | S1: Q_Info_EnG$ineerinG$code | T1: Q_Info_Insurances | U1: Q_Info_Insurancescode | V1: Q_FloodFuture | W1: Q_FloodFuturecode | X1: Q_ClimateChanG$e | Y1: Q_ClimateChanG$ecode | Z1: Q_Threat | AA1: Q_Threatcode
A2: 1 | B2: True | C2: 45937.248 | E2: t3p3 | F2: Nee, ik heb G$een ervarinG$ met overstrominG$en | G2: 1 | H2: Eén keer in de afG$elopen zes maanden | I2: 3 | J2: Eén keer per week | K2: 5 | L2: Eén keer per maand | M2: 4 | N2: Eén keer per maand | O2: 4 | P2: Eén keer per maand | Q2: 4 | R2: Eén keer per maand | S2: 4 | T2: Eén keer per daG$ | U2: 6 | V2: Neutraal | W2: 3 | X2: Een kleine toename | Y2: 2 | Z2: Ik zal eniG$e schade oplopen | AA2: 4
A3: 2 | B3: True | C3: 45937.251 | D3: Ja, ik G$a akkoord met vrijwilliG$e deelname (bedankt voor uw medewerkinG$)! | E3: t4p5 | F3: Nee, ik heb G$een ervarinG$ met overstrominG$en | G3: 1 | H3: Nooit | I3: 1 | J3: Eén keer in de afG$elopen zes maanden | K3: 3 | L3: Nooit | M3: 1 | N3: Eén keer per maand | O3: 4 | P3: Eén keer in de afG$elopen zes maanden | Q3: 3 | R3: Eén keer in het afG$elopen jaar | S3: 2 | T3: Eén keer in het afG$elopen jaar | U3: 2 | V3: Onwaarschijnlijk | W3: 2 | X3: Een kleine toename | Y3: 2 | Z3: G$een, Ik zal niet overstromen | AA3: 1
A4: 3 | B4: True | C4: 45937.251 | D4: Ja, ik G$a akkoord met vrijwilliG$e deelname (bedankt voor uw medewerkinG$)! | E4: t3p4 | F4: Nee, ik heb G$een ervarinG$ met overstrominG$en | G4: 1 | H4: Eén keer per week | I4: 5 | J4: Eén keer per week | K4: 5 | L4: Eén keer per maand | M4: 4 | N4: Eén keer per daG$ | O4: 6 | P4: Eén keer per daG$ | Q4: 6 | R4: Eén keer per maand | S4: 4 | T4: Eén keer per maand | U4: 4 | V4: Neutraal | W4: 3 | X4: Een G$emiddelde toename | Y4: 3 | Z4: Ik zal eniG$e schade oplopen | AA4: 4
A5: 4 | B5: True | C5: 45937.251 | D5: Ja, ik G$a akkoord met vrijwilliG$e deelname (bedankt voor uw medewerkinG$)! | E5: t3p2 | F5: Ja, met eniG$e verstorinG$en of schade | G5: 4 | H5: Eén keer in het afG$elopen jaar | I5: 2 | J5: Eén keer in het afG$elopen jaar | K5: 2 | L5: Nooit | M5: 1 | N5: Eén keer in het afG$elopen jaar | O5: 2 | P5: Eén keer in het afG$elopen jaar | Q5: 2 | R5: Nooit | S5: 1 | T5: Nooit | U5: 1 | V5: Zeer onwaarschijnlijk | W5: 1 | X5: G$een toename | Y5: 1 | Z5: G$een, Ik zal niet overstromen | AA5: 1
A6: 5 | B6: True | C6: 45937.251 | D6: Ja, ik G$a akkoord met vrijwilliG$e deelname (bedankt voor uw medewerkinG$)! | E6: 3 en | F6: Nee, ik heb G$een ervarinG$ met overstrominG$en | G6: 1 | H6: Eén keer per maand | I6: 4 | J6: Eén keer per week | K6: 5 | L6: Eén keer in de afG$elopen zes maanden | M6: 3 | N6: Eén keer per week | O6: 5 | P6: Eén keer per week | Q6: 5 | R6: Nooit | S6: 1 | T6: Eén keer per maand | U6: 4 | V6: Zeer onwaarschijnlijk | W6: 1 | X6: Een kleine toename | Y6: 2 | Z6: Als ik overstroom, zal ik G$een schade hebben | AA6: 2
A7: 6 | B7: True | C7: 45937.251 | D7: Ja, ik G$a akkoord met vrijwilliG$e deelname (bedankt voor uw medewerkinG$)! | E7: t2p4 | F7: Ja, met lichte verstorinG$en of schade | G7: 3 | H7: Nooit | I7: 1 | J7: Eén keer per maand | K7: 4 | L7: Nooit | M7: 1 | N7: Eén keer per maand | O7: 4 | P7: Nooit | Q7: 1 | R7: Nooit | S7: 1 | T7: Nooit | U7: 1 | V7: Waarschijnlijk | W7: 4 | X7: Een kleine toename | Y7: 2 | Z7: Ik zal eniG$e schade oplopen | AA7: 4
A8: 7 | B8: True | C8: 45937.251 | D8: Ja, ik G$a akkoord met vrijwilliG$e deelname (bedankt voor uw medewerkinG$)! | E8: t2p5 | F8: Ja, met eniG$e verstorinG$en of schade | G8: 4 | H8: Eén keer in het afG$elopen jaar | I8: 2 | J8: Eén keer in het afG$elopen jaar | K8: 2 | L8: Eén keer in de afG$elopen zes maanden | M8: 3 | N8: Eén keer per maand | O8: 4 | P8: Eén keer in de afG$elopen zes maanden | Q8: 3 | R8: Eén keer in de afG$elopen zes maanden | S8: 3 | T8: Eén keer per week | U8: 5 | V8: Zeer onwaarschijnlijk | W8: 1 | X8: G$een toename | Y8: 1 | Z8: G$een, Ik zal niet overstromen | AA8: 1
A9: 8 | B9: True | C9: 45937.252 | D9: Ja, ik G$a akkoord met vrijwilliG$e deelname (bedankt voor uw medewerkinG$)! | E9: t4p6 | F9: Nee, ik heb G$een ervarinG$ met overstrominG$en | G9: 1 | H9: Eén keer in het afG$elopen jaar | I9: 2 | J9: Eén keer in de afG$elopen zes maanden | K9: 3 | L9: Eén keer in het afG$elopen jaar | M9: 2 | N9: Eén keer in het afG$elopen jaar | O9: 2 | P9: Nooit | Q9: 1 | R9: Eén keer in het afG$elopen jaar | S9: 2 | T9: Eén keer in het afG$elopen jaar | U9: 2 | V9: Onwaarschijnlijk | W9: 2 | X9: Een kleine toename | Y9: 2 | Z9: Ik zal eniG$e schade oplopen | AA9: 4
A10: 9 | B10: True | C10: 45937.252 | D10: Ja, ik G$a akkoord met vrijwilliG$e deelname (bedankt voor uw medewerkinG$)! | E10: t2p6 | F10: Ja, maar zonder verstorinG$en of schade | G10: 2 | H10: Nooit | I10: 1 | J10: Eén keer in het afG$elopen jaar | K10: 2 | L10: Eén keer in de afG$elopen zes maanden | M10: 3 | N10: Eén keer in de afG$elopen zes maanden | O10: 3 | P10: Eén keer in het afG$elopen jaar | Q10: 2 | R10: Nooit | S10: 1 | T10: Eén keer per maand | U10: 4 | V10: Zeer onwaarschijnlijk | W10: 1 | X10: Een kleine toename | Y10: 2 | Z10: Ik zou lichte schade kunnen oplopen | AA10: 3
A11: 10 | B11: True | C11: 45937.252 | D11: Ja, ik G$a akkoord met vrijwilliG$e deelname (bedankt voor uw medewerkinG$)! | E11: t4p4 | F11: Ja, met lichte verstorinG$en of schade | G11: 3 | H11: Eén keer in de afG$elopen zes maanden | I11: 3 | J11: Eén keer per daG$ | K11: 6 | L11: Eén keer in de afG$elopen zes maanden | M11: 3 | N11: Eén keer per daG$ | O11: 6 | P11: Nooit | Q11: 1 | R11: Eén keer in het afG$elopen jaar | S11: 2 | T11: Eén keer per maand | U11: 4 | V11: Waarschijnlijk | W11: 4 | X11: Een G$rote toename | Y11: 4 | Z11: Ik zou lichte schade kunnen oplopen | AA11: 3
A12: 11 | B12: True | C12: 45937.252 | D12: Ja, ik G$a akkoord met vrijwilliG$e deelname (bedankt voor uw medewerkinG$)! | E12: t3p5 | F12: Nee, ik heb G$een ervarinG$ met overstrominG$en | G12: 1 | H12: Eén keer in de afG$elopen zes maanden | I12: 3 | J12: Eén keer per maand | K12: 4 | L12: Nooit | M12: 1 | N12: Eén keer in de afG$elopen zes maanden | O12: 3 | P12: Eén keer in de afG$elopen zes maanden | Q12: 3 | R12: Nooit | S12: 1 | T12: Eén keer per maand | U12: 4 | V12: Zeer onwaarschijnlijk | W12: 1 | X12: G$een toename | Y12: 1 | Z12: G$een, Ik zal niet overstromen | AA12: 1
A13: 12 | B13: True | C13: 45937.252 | D13: Ja, ik G$a akkoord met vrijwilliG$e deelname (bedankt voor uw medewerkinG$)! | E13: t1p1 | F13: Nee, ik heb G$een ervarinG$ met overstrominG$en | G13: 1 | H13: Nooit | I13: 1 | J13: Nooit | K13: 1 | L13: Nooit | M13: 1 | N13: Eén keer in de afG$elopen zes maanden | O13: 3 | P13: Nooit | Q13: 1 | R13: Nooit | S13: 1 | T13: Nooit | U13: 1 | V13: Zeer onwaarschijnlijk | W13: 1 | X13: G$een toename | Y13: 1 | Z13: G$een, Ik zal niet overstromen | AA13: 1
A14: 13 | B14: True | C14: 45937.252 | D14: Ja, ik G$a akkoord met vrijwilliG$e deelname (bedankt voor uw medewerkinG$)! | E14: t1p3 | F14: Ja, met eniG$e verstorinG$en of schade | G14: 4 | H14: Eén keer in de afG$elopen zes maanden | I14: 3 | J14: Eén keer per daG$ | K14: 6 | L14: Eén keer in de afG$elopen zes maanden | M14: 3 | N14: Eén keer per daG$ | O14: 6 | P14: Eén keer per week | Q14: 5 | R14: Eén keer in het afG$elopen jaar | S14: 2 | T14: Eén keer per maand | U14: 4 | V14: Zeer onwaarschijnlijk | W14: 1 | X14: Een kleine toename | Y14: 2 | Z14: G$een, Ik zal niet overstromen | AA14: 1
... A24: 23 | B24: True | C24: 45937.256 | D24: Ja, ik G$a akkoord met vrijwilliG$e deelname (bedankt voor uw medewerkinG$)! | E24: t2p2 | F24: Nee, ik heb G$een ervarinG$ met overstrominG$en | G24: 1 | H24: Eén keer in het afG$elopen jaar | I24: 2 | J24: Eén keer in de afG$elopen zes maanden | K24: 3 | L24: Eén keer in de afG$elopen zes maanden | M24: 3 | N24: Eén keer per maand | O24: 4 | P24: Nooit | Q24: 1 | R24: Nooit | S24: 1 | T24: Nooit | U24: 1 | V24: Zeer onwaarschijnlijk | W24: 1 | X24: Een kleine toename | Y24: 2 | Z24: Ik zal eniG$e schade oplopen | AA24: 4
F25: Response options
F26: =+Settings!$F$7 -> 1 = No, I do not have a flood experience | G26: =+COUNTIF(G$2:G$24,1) -> 14 | H26: =+Settings!$F$8 -> 1 = Never | I26: =+COUNTIF(I$2:I$24,1) -> 5 | J26: =+Settings!$F$8 -> 1 = Never | K26: =+COUNTIF(K$2:K$24,1) -> 1 | L26: =+Settings!$F$8 -> 1 = Never | M26: =+COUNTIF(M$2:M$24,1) -> 7 | N26: =+Settings!$F$8 -> 1 = Never | O26: =+COUNTIF(O$2:O$24,1) -> 0 | P26: =+Settings!$F$8 -> 1 = Never | Q26: =+COUNTIF(Q$2:Q$24,1) -> 6 | R26: =+Settings!$F$8 -> 1 = Never | S26: =+COUNTIF(S$2:S$24,1) -> 13 | T26: =+Settings!$F$8 -> 1 = Never | U26: =+COUNTIF(U$2:U$24,1) -> 6 | V26: =+Settings!$F$16 -> 1 = Very unlikely | W26: =+COUNTIF(W$2:W$24,1) -> 13 | X26: =+Settings!$F$17 -> 1 = No increase at all | Y26: =+COUNTIF(Y$2:Y$24,1) -> 7 | Z26: =+Settings!$F$18 -> 1 = I won't get flooded | AA26: =+COUNTIF(AA$2:AA$24,1) -> 10
F27: =+Settings!$G$7 -> 2 = Yes, but without disruptions or damages | G27: =+COUNTIF(G$2:G$24,2) -> 1 | H27: =+Settings!$G$8 -> 2 = Once in the last year | I27: =+COUNTIF(I$2:I$24,2) -> 7 | J27: =+Settings!$G$8 -> 2 = Once in the last year | K27: =+COUNTIF(K$2:K$24,2) -> 5 | L27: =+Settings!$G$8 -> 2 = Once in the last year | M27: =+COUNTIF(M$2:M$24,2) -> 4 | N27: =+Settings!$G$8 -> 2 = Once in the last year | O27: =+COUNTIF(O$2:O$24,2) -> 3 | P27: =+Settings!$G$8 -> 2 = Once in the last year | Q27: =+COUNTIF(Q$2:Q$24,2) -> 3 | R27: =+Settings!$G$8 -> 2 = Once in the last year | S27: =+COUNTIF(S$2:S$24,2) -> 4 | T27: =+Settings!$G$8 -> 2 = Once in the last year | U27: =+COUNTIF(U$2:U$24,2) -> 3 | V27: =+Settings!$G$16 -> 2 = Unlikely | W27: =+COUNTIF(W$2:W$24,2) -> 3 | X27: =+Settings!$G$17 -> 2 = A little increase | Y27: =+COUNTIF(Y$2:Y$24,2) -> 11 | Z27: =+Settings!$G$18 -> 2 = If I get flooded, I won't get damaged | AA27: =+COUNTIF(AA$2:AA$24,2) -> 3
F28: =+Settings!$H$7 -> 3 = Yes, with minor disruptions or damages | G28: =+COUNTIF(G$2:G$24,3) -> 3 | H28: =+Settings!$H$8 -> 3 = Once in the last six months | I28: =+COUNTIF(I$2:I$24,3) -> 7 | J28: =+Settings!$H$8 -> 3 = Once in the last six months | K28: =+COUNTIF(K$2:K$24,3) -> 4 | L28: =+Settings!$H$8 -> 3 = Once in the last six months | M28: =+COUNTIF(M$2:M$24,3) -> 8 | N28: =+Settings!$H$8 -> 3 = Once in the last six months | O28: =+COUNTIF(O$2:O$24,3) -> 4 | P28: =+Settings!$H$8 -> 3 = Once in the last six months | Q28: =+COUNTIF(Q$2:Q$24,3) -> 7 | R28: =+Settings!$H$8 -> 3 = Once in the last six months | S28: =+COUNTIF(S$2:S$24,3) -> 4 | T28: =+Settings!$H$8 -> 3 = Once in the last six months | U28: =+COUNTIF(U$2:U$24,3) -> 2 | V28: =+Settings!$H$16 -> 3 = Neutral | W28: =+COUNTIF(W$2:W$24,3) -> 3 | X28: =+Settings!$H$17 -> 3 = A moderate increase | Y28: =+COUNTIF(Y$2:Y$24,3) -> 1 | Z28: =+Settings!$H$18 -> 3 = I might suffer minor damage | AA28: =+COUNTIF(AA$2:AA$24,3) -> 2
F29: =+Settings!$I$7 -> 4 = Yes, with some disruptions or damages | G29: =+COUNTIF(G$2:G$24,4) -> 4 | H29: =+Settings!$I$8 -> 4 = Once a month | I29: =+COUNTIF(I$2:I$24,4) -> 2 | J29: =+Settings!$I$8 -> 4 = Once a month | K29: =+COUNTIF(K$2:K$24,4) -> 3 | L29: =+Settings!$I$8 -> 4 = Once a month | M29: =+COUNTIF(M$2:M$24,4) -> 2 | N29: =+Settings!$I$8 -> 4 = Once a month | O29: =+COUNTIF(O$2:O$24,4) -> 7 | P29: =+Settings!$I$8 -> 4 = Once a month | Q29: =+COUNTIF(Q$2:Q$24,4) -> 1 | R29: =+Settings!$I$8 -> 4 = Once a month | S29: =+COUNTIF(S$2:S$24,4) -> 2 | T29: =+Settings!$I$8 -> 4 = Once a month | U29: =+COUNTIF(U$2:U$24,4) -> 8 | V29: =+Settings!$I$16 -> 4 = Likely | W29: =+COUNTIF(W$2:W$24,4) -> 4 | X29: =+Settings!$I$17 -> 4 = A big increase | Y29: =+COUNTIF(Y$2:Y$24,4) -> 4 | Z29: =+Settings!$I$18 -> 4 = I will suffer some damage | AA29: =+COUNTIF(AA$2:AA$24,4) -> 8
F30: =+Settings!$J$7 -> 5 = Yes, with serious disruptions or damages | G30: =+COUNTIF(G$2:G$24,5) -> 1 | H30: =+Settings!$J$8 -> 5 = Once a week | I30: =+COUNTIF(I$2:I$24,5) -> 2 | J30: =+Settings!$J$8 -> 5 = Once a week | K30: =+COUNTIF(K$2:K$24,5) -> 4 | L30: =+Settings!$J$8 -> 5 = Once a week | M30: =+COUNTIF(M$2:M$24,5) -> 2 | N30: =+Settings!$J$8 -> 5 = Once a week | O30: =+COUNTIF(O$2:O$24,5) -> 2 | P30: =+Settings!$J$8 -> 5 = Once a week | Q30: =+COUNTIF(Q$2:Q$24,5) -> 3 | R30: =+Settings!$J$8 -> 5 = Once a week | S30: =+COUNTIF(S$2:S$24,5) -> 0 | T30: =+Settings!$J$8 -> 5 = Once a week | U30: =+COUNTIF(U$2:U$24,5) -> 3 | V30: =+Settings!$J$16 -> 5 = Very likely | W30: =+COUNTIF(W$2:W$24,5) -> 0 | X30: =+Settings!$J$17 -> 5 = An extreme increase | Y30: =+COUNTIF(Y$2:Y$24,5) -> 0 | Z30: =+Settings!$J$18 -> 5 = I will get seriously damaged | AA30: =+COUNTIF(AA$2:AA$24,5) -> 0
H31: =+Settings!$K$8 -> 6 = Once a day | I31: =+COUNTIF(I$2:I$24,6) -> 0 | J31: =+Settings!$K$8 -> 6 = Once a day | K31: =+COUNTIF(K$2:K$24,6) -> 6 | L31: =+Settings!$K$8 -> 6 = Once a day | M31: =+COUNTIF(M$2:M$24,6) -> 0 | N31: =+Settings!$K$8 -> 6 = Once a day | O31: =+COUNTIF(O$2:O$24,6) -> 7 | P31: =+Settings!$K$8 -> 6 = Once a day | Q31: =+COUNTIF(Q$2:Q$24,6) -> 3 | R31: =+Settings!$K$8 -> 6 = Once a day | S31: =+COUNTIF(S$2:S$24,6) -> 0 | T31: =+Settings!$K$8 -> 6 = Once a day | U31: =+COUNTIF(U$2:U$24,6) -> 1
F32: Mean | G32: {=+AVERAGE(VALUE(G$2:G$24))} -> 2 | H32: Mean | I32: {=+AVERAGE(VALUE(I$2:I$24))} -> 2.5217391 | J32: Mean | K32: {=+AVERAGE(VALUE(K$2:K$24))} -> 3.9565217 | L32: Mean | M32: {=+AVERAGE(VALUE(M$2:M$24))} -> 2.4782609 | N32: Mean | O32: {=+AVERAGE(VALUE(O$2:O$24))} -> 4.2608696 | P32: Mean | Q32: {=+AVERAGE(VALUE(Q$2:Q$24))} -> 3.0434783 | R32: Mean | S32: {=+AVERAGE(VALUE(S$2:S$24))} -> 1.7826087 | T32: Mean | U32: {=+AVERAGE(VALUE(U$2:U$24))} -> 3.0869565 | V32: Mean | W32: {=+AVERAGE(VALUE(W$2:W$24))} -> 1.9130435 | X32: Mean | Y32: {=+AVERAGE(VALUE(Y$2:Y$24))} -> 2.0869565 | Z32: Mean | AA32: {=+AVERAGE(VALUE(AA$2:AA$24))} -> 2.3478261
F33: Median | G33: {=+MEDIAN(VALUE(G$26:G$30))} -> 3 | H33: Median | I33: {=+MEDIAN(VALUE(I$26:I$30))} -> 5 | J33: Median | K33: {=+MEDIAN(VALUE(K$26:K$30))} -> 4 | L33: Median | M33: {=+MEDIAN(VALUE(M$26:M$30))} -> 4 | N33: Median | O33: {=+MEDIAN(VALUE(O$26:O$30))} -> 3 | P33: Median | Q33: {=+MEDIAN(VALUE(Q$26:Q$30))} -> 3 | R33: Median | S33: {=+MEDIAN(VALUE(S$26:S$30))} -> 4 | T33: Median | U33: {=+MEDIAN(VALUE(U$26:U$30))} -> 3 | V33: Median | W33: {=+MEDIAN(VALUE(W$26:W$30))} -> 3 | X33: Median | Y33: {=+MEDIAN(VALUE(Y$26:Y$30))} -> 4 | Z33: Median | AA33: {=+MEDIAN(VALUE(AA$26:AA$30))} -> 3

Sheet 250923
A1: id | B1: Q_SurveyFinished | C1: Q_RecordedDate | D1: Q_Consent | E1: Q_PlayerNumber | F1: Q_Experience | G1: Q_Experiencecode | H1: Q_Info_Government | I1: Q_Info_Governmentcode | J1: Q_Info_WeatherForecast | K1: Q_Info_WeatherForecastcode | L1: Q_Info_Scientific | M1: Q_Info_Scientificcode | N1: Q_Info_GeneralMedia | O1: Q_Info_GeneralMediacode | P1: Q_Info_SocialMedia | Q1: Q_Info_SocialMediacode | R1: Q_Info_Engineering | S1: Q_Info_Engineeringcode | T1: Q_Info_Insurances | U1: Q_Info_Insurancescode | V1: Q_FloodFuture | W1: Q_FloodFuturecode | X1: Q_ClimateChange | Y1: Q_ClimateChangecode | Z1: Q_Threat | AA1: Q_Threatcode
A2: 1 | B2: True | C2: 45923.104 | D2: Yes, I agree to voluntarily participate (thanks for your collaboration)! | E2: t1p3 | F2: No, I do not have a flood experience | G2: 1 | H2: Once in the last year | I2: 2 | J2: Once in the last year | K2: 2 | L2: Never | M2: 1 | N2: Once in the last year | O2: 2 | P2: Never | Q2: 1 | R2: Never | S2: 1 | T2: Never | U2: 1 | V2: Unlikely | W2: 2 | X2: A little increase | Y2: 2 | Z2: I might suffer minor damage | AA2: 3
A3: 2 | B3: True | C3: 45923.104 | D3: Yes, I agree to voluntarily participate (thanks for your collaboration)! | E3: t1p1 | F3: Yes, with minor disruptions or damages | G3: 3 | H3: Never | I3: 1 | J3: Once in the last year | K3: 2 | L3: Once in the last year | M3: 2 | N3: Once in the last six months | O3: 3 | P3: Once in the last six months | Q3: 3 | R3: Never | S3: 1 | T3: Never | U3: 1 | V3: Likely | W3: 4 | X3: An extreme increase | Y3: 5 | Z3: I will suffer some damage | AA3: 4
A4: 3 | B4: True | C4: 45923.104 | D4: Yes, I agree to voluntarily participate (thanks for your collaboration)! | E4: t2p1 | F4: No, I do not have a flood experience | G4: 1 | H4: Never | I4: 1 | J4: Never | K4: 1 | L4: Never | M4: 1 | N4: Once in the last year | O4: 2 | P4: Once in the last year | Q4: 2 | R4: Once in the last year | S4: 2 | T4: Once in the last six months | U4: 3 | V4: Very unlikely | W4: 1 | X4: A big increase | Y4: 4 | Z4: I won't get flooded | AA4: 1
A5: 4 | B5: True | C5: 45923.105 | D5: Yes, I agree to voluntarily participate (thanks for your collaboration)! | E5: t1p5 | F5: Yes, with some disruptions or damages | G5: 4 | H5: Never | I5: 1 | J5: Once in the last six months | K5: 3 | L5: Never | M5: 1 | N5: Once in the last six months | O5: 3 | P5: Once in the last six months | Q5: 3 | R5: Never | S5: 1 | T5: Never | U5: 1 | V5: Likely | W5: 4 | X5: An extreme increase | Y5: 5 | Z5: I will suffer some damage | AA5: 4
A6: 5 | B6: True | C6: 45923.105 | D6: Yes, I agree to voluntarily participate (thanks for your collaboration)! | E6: t2 p5 | F6: No, I do not have a flood experience | G6: 1 | H6: Once in the last year | I6: 2 | J6: Once in the last year | K6: 2 | L6: Never | M6: 1 | N6: Once in the last six months | O6: 3 | P6: Once in the last six months | Q6: 3 | R6: Never | S6: 1 | T6: Never | U6: 1 | V6: Unlikely | W6: 2 | X6: A big increase | Y6: 4 | Z6: If I get flooded, I won't get damaged | AA6: 2
A7: 6 | B7: True | C7: 45923.105 | D7: Yes, I agree to voluntarily participate (thanks for your collaboration)! | E7: 2, t2 | F7: No, I do not have a flood experience | G7: 1 | H7: Never | I7: 1 | J7: Once in the last year | K7: 2 | L7: Never | M7: 1 | N7: Once in the last year | O7: 2 | P7: Once in the last year | Q7: 2 | R7: Never | S7: 1 | T7: Never | U7: 1 | V7: Very unlikely | W7: 1 | X7: A little increase | Y7: 2 | Z7: I will suffer some damage | AA7: 4
A8: 7 | B8: True | C8: 45923.105 | D8: Yes, I agree to voluntarily participate (thanks for your collaboration)! | E8: t1p2 | F8: No, I do not have a flood experience | G8: 1 | H8: Once in the last six months | I8: 3 | J8: Once in the last six months | K8: 3 | L8: Never | M8: 1 | N8: Once in the last six months | O8: 3 | P8: Once in the last six months | Q8: 3 | R8: Never | S8: 1 | T8: Never | U8: 1 | V8: Unlikely | W8: 2 | X8: A moderate increase | Y8: 3 | Z8: If I get flooded, I won't get damaged | AA8: 2
A9: 8 | B9: True | C9: 45923.106 | D9: Yes, I agree to voluntarily participate (thanks for your collaboration)! | E9: t1p7 | F9: Yes, with serious disruptions or damages | G9: 5 | H9: Once a month | I9: 4 | J9: Once in the last six months | K9: 3 | L9: Once a month | M9: 4 | N9: Once a month | O9: 4 | P9: Once in the last six months | Q9: 3 | R9: Once in the last year | S9: 2 | T9: Never | U9: 1 | V9: Very likely | W9: 5 | X9: A big increase | Y9: 4 | Z9: I might suffer minor damage | AA9: 3
A10: 9 | B10: True | C10: 45923.106 | D10: Yes, I agree to voluntarily participate (thanks for your collaboration)! | E10: t1p6 | F10: No, I do not have a flood experience | G10: 1 | H10: Never | I10: 1 | J10: Never | K10: 1 | L10: Never | M10: 1 | N10: Never | O10: 1 | P10: Never | Q10: 1 | R10: Never | S10: 1 | T10: Never | U10: 1 | V10: Unlikely | W10: 2 | X10: An extreme increase | Y10: 5 | Z10: I will get seriously damaged | AA10: 5
A11: 10 | B11: True | C11: 45923.106 | D11: Yes, I agree to voluntarily participate (thanks for your collaboration)! | E11: t2p3 | F11: No, I do not have a flood experience | G11: 1 | H11: Never | I11: 1 | J11: Never | K11: 1 | L11: Once in the last year | M11: 2 | N11: Once in the last six months | O11: 3 | P11: Once in the last six months | Q11: 3 | R11: Once in the last year | S11: 2 | T11: Never | U11: 1 | V11: Neutral | W11: 3 | X11: A big increase | Y11: 4 | Z11: I might suffer minor damage | AA11: 3
A12: 11 | B12: True | C12: 45923.106 | D12: Yes, I agree to voluntarily participate (thanks for your collaboration)! | E12: t4p6 | F12: No, I do not have a flood experience | G12: 1 | H12: Never | I12: 1 | J12: Once in the last six months | K12: 3 | L12: Never | M12: 1 | N12: Once in the last six months | O12: 3 | P12: Once in the last six months | Q12: 3 | R12: Never | S12: 1 | T12: Never | U12: 1 | V12: Neutral | W12: 3 | X12: A moderate increase | Y12: 3 | Z12: I might suffer minor damage | AA12: 3
A13: 12 | B13: True | C13: 45923.106 | D13: Yes, I agree to voluntarily participate (thanks for your collaboration)! | E13: t4p2 | F13: No, I do not have a flood experience | G13: 1 | H13: Once in the last year | I13: 2 | J13: Once in the last year | K13: 2 | L13: Once in the last year | M13: 2 | N13: Once in the last year | O13: 2 | P13: Once in the last six months | Q13: 3 | R13: Once in the last year | S13: 2 | T13: Once in the last year | U13: 2 | V13: Neutral | W13: 3 | X13: A big increase | Y13: 4 | Z13: I might suffer minor damage | AA13: 3
... A27: 26 | B27: True | C27: 45923.109 | D27: Yes, I agree to voluntarily participate (thanks for your collaboration)! | E27: t2p2 | F27: No, I do not have a flood experience | G27: 1 | H27: Never | I27: 1 | J27: Once a week | K27: 5 | L27: Never | M27: 1 | N27: Once a month | O27: 4 | P27: Once a day | Q27: 6 | R27: Never | S27: 1 | T27: Never | U27: 1 | V27: Neutral | W27: 3 | X27: A big increase | Y27: 4 | Z27: I might suffer minor damage | AA27: 3
A28: 27 | B28: True | C28: 45923.256 | D28: No, I prefer not to participate (the survey ends, and you kindly wait for others to finish)
A29: 28 | B29: True | C29: 45923.257 | D29: Yes, I agree to voluntarily participate (thanks for your collaboration)! | E29: t8p1 | F29: Yes, with some disruptions or damages | G29: 4 | H29: Never | I29: 1 | J29: Once a day | K29: 6 | L29: Once a month | M29: 4 | N29: Never | O29: 1 | P29: Once a week | Q29: 5 | R29: Never | S29: 1 | T29: Never | U29: 1 | V29: Likely | W29: 4 | X29: An extreme increase | Y29: 5 | Z29: I might suffer minor damage | AA29: 3
A30: 29 | B30: True | C30: 45923.258 | D30: Yes, I agree to voluntarily participate (thanks for your collaboration)! | E30: t8p2 | F30: Yes, with minor disruptions or damages | G30: 3 | H30: Once in the last six months | I30: 3 | J30: Once in the last year | K30: 2 | L30: Never | M30: 1 | N30: Once in the last year | O30: 2 | P30: Once in the last year | Q30: 2 | R30: Never | S30: 1 | T30: Never | U30: 1 | V30: Likely | W30: 4 | X30: An extreme increase | Y30: 5 | Z30: I might suffer minor damage | AA30: 3
A31: 30 | B31: True | C31: 45923.258 | D31: Yes, I agree to voluntarily participate (thanks for your collaboration)! | E31: t8p7 | F31: No, I do not have a flood experience | G31: 1 | H31: Once in the last year | I31: 2 | J31: Once in the last year | K31: 2 | L31: Never | M31: 1 | N31: Once a day | O31: 6 | P31: Once a day | Q31: 6 | R31: Never | S31: 1 | T31: Never | U31: 1 | V31: Unlikely | W31: 2 | X31: A big increase | Y31: 4 | Z31: I will get seriously damaged | AA31: 5
A32: 31 | B32: True | C32: 45923.258 | D32: Yes, I agree to voluntarily participate (thanks for your collaboration)! | E32: t7p5 | F32: No, I do not have a flood experience | G32: 1 | H32: Never | I32: 1 | J32: Once a month | K32: 4 | L32: Never | M32: 1 | N32: Once in the last year | O32: 2 | P32: Never | Q32: 1 | R32: Never | S32: 1 | T32: Never | U32: 1 | V32: Unlikely | W32: 2 | X32: A moderate increase | Y32: 3 | Z32: I might suffer minor damage | AA32: 3
A33: 32 | B33: True | C33: 45923.258 | D33: Yes, I agree to voluntarily participate (thanks for your collaboration)! | E33: t5p5 | F33: No, I do not have a flood experience | G33: 1 | H33: Once a month | I33: 4 | J33: Once a month | K33: 4 | L33: Never | M33: 1 | N33: Once a month | O33: 4 | P33: Once a month | Q33: 4 | R33: Never | S33: 1 | T33: Never | U33: 1 | V33: Likely | W33: 4 | X33: A big increase | Y33: 4 | Z33: I might suffer minor damage | AA33: 3
A34: 33 | B34: True | C34: 45923.258 | D34: Yes, I agree to voluntarily participate (thanks for your collaboration)! | E34: t5p3 | F34: No, I do not have a flood experience | G34: 1 | H34: Never | I34: 1 | J34: Never | K34: 1 | L34: Never | M34: 1 | N34: Never | O34: 1 | P34: Never | Q34: 1 | T34: Never | U34: 1 | V34: Very unlikely | W34: 1 | X34: A little increase | Y34: 2 | Z34: If I get flooded, I won't get damaged | AA34: 2
A35: 34 | B35: True | C35: 45923.258 | D35: Yes, I agree to voluntarily participate (thanks for your collaboration)! | E35: t8p6 | F35: Yes, but without disruptions or damages | G35: 2 | H35: Never | I35: 1 | J35: Once in the last year | K35: 2 | L35: Never | M35: 1 | N35: Never | O35: 1 | P35: Never | Q35: 1 | R35: Never | S35: 1 | T35: Never | U35: 1 | V35: Likely | W35: 4 | X35: A moderate increase | Y35: 3 | Z35: I might suffer minor damage | AA35: 3
A36: 35 | B36: True | C36: 45923.259 | D36: Yes, I agree to voluntarily participate (thanks for your collaboration)! | E36: t7p1 | F36: No, I do not have a flood experience | G36: 1 | H36: Never | I36: 1 | J36: Once a month | K36: 4 | L36: Never | M36: 1 | N36: Once in the last six months | O36: 3 | P36: Never | Q36: 1 | R36: Never | S36: 1 | T36: Never | U36: 1 | V36: Likely | W36: 4 | X36: A big increase | Y36: 4 | Z36: I will suffer some damage | AA36: 4
A37: 36 | B37: True | C37: 45923.259 | D37: Yes, I agree to voluntarily participate (thanks for your collaboration)! | E37: t5p1 | F37: No, I do not have a flood experience | G37: 1 | H37: Once in the last six months | I37: 3 | J37: Once in the last year | K37: 2 | L37: Once in the last six months | M37: 3 | N37: Once in the last six months | O37: 3 | P37: Never | Q37: 1 | R37: Never | S37: 1 | T37: Never | U37: 1 | V37: Unlikely | W37: 2 | X37: A big increase | Y37: 4 | Z37: I might suffer minor damage | AA37: 3
A38: 37 | B38: True | C38: 45923.259 | D38: Yes, I agree to voluntarily participate (thanks for your collaboration)! | E38: t6p2 | F38: No, I do not have a flood experience | G38: 1 | H38: Never | I38: 1 | J38: Once a day | K38: 6 | L38: Once a month | M38: 4 | N38: Once a week | O38: 5 | P38: Once a day | Q38: 6 | R38: Never | S38: 1 | T38: Never | U38: 1 | V38: Very unlikely | W38: 1 | X38: A moderate increase | Y38: 3 | Z38: I won't get flooded | AA38: 1
A39: 38 | B39: True | C39: 45923.26 | D39: Yes, I agree to voluntarily participate (thanks for your collaboration)! | E39: t5p2 | F39: No, I do not have a flood experience | G39: 1 | H39: Never | I39: 1 | J39: Once in the last six months | K39: 3 | L39: Never | M39: 1 | N39: Once a month | O39: 4 | P39: Once a month | Q39: 4 | R39: Never | S39: 1 | T39: Never | U39: 1 | V39: Unlikely | W39: 2 | X39: A big increase | Y39: 4 | Z39: I might suffer minor damage | AA39: 3
A40: 39 | B40: True | C40: 45923.26 | D40: Yes, I agree to voluntarily participate (thanks for your collaboration)! | E40: t5p7 | F40: No, I do not have a flood experience | G40: 1 | H40: Once in the last six months | I40: 3 | J40: Once a month | K40: 4 | L40: Never | M40: 1 | N40: Once in the last six months | O40: 3 | P40: Once in the last six months | Q40: 3 | R40: Never | S40: 1 | T40: Never | U40: 1 | V40: Likely | W40: 4 | X40: A big increase | Y40: 4 | Z40: I might suffer minor damage | AA40: 3
A41: 40 | B41: True | C41: 45923.26 | D41: Yes, I agree to voluntarily participate (thanks for your collaboration)! | E41: t7p3 | F41: Yes, but without disruptions or damages | G41: 2 | H41: Never | I41: 1 | J41: Never | K41: 1 | L41: Once in the last year | M41: 2 | N41: Once in the last year | O41: 2 | P41: Once in the last year | Q41: 2 | R41: Never | S41: 1 | T41: Never | U41: 1 | V41: Likely | W41: 4 | X41: A big increase | Y41: 4 | Z41: I will get seriously damaged | AA41: 5
A42: 41 | B42: True | C42: 45923.26 | D42: Yes, I agree to voluntarily participate (thanks for your collaboration)! | E42: t6p5 | F42: No, I do not have a flood experience | G42: 1 | H42: Never | I42: 1 | J42: Once in the last six months | K42: 3 | L42: Once in the last six months | M42: 3 | N42: Once in the last six months | O42: 3 | P42: Once in the last six months | Q42: 3 | R42: Never | S42: 1 | T42: Never | U42: 1 | V42: Unlikely | W42: 2 | X42: A little increase | Y42: 2 | Z42: I will suffer some damage | AA42: 4
A43: 42 | B43: True | C43: 45923.26 | D43: Yes, I agree to voluntarily participate (thanks for your collaboration)! | E43: t6p3 | F43: No, I do not have a flood experience | G43: 1 | H43: Never | I43: 1 | J43: Once in the last year | K43: 2 | L43: Once in the last year | M43: 2 | N43: Once in the last six months | O43: 3 | P43: Once in the last year | Q43: 2 | R43: Never | S43: 1 | T43: Never | U43: 1 | V43: Unlikely | W43: 2 | X43: A little increase | Y43: 2 | Z43: I might suffer minor damage | AA43: 3
A44: 43 | B44: True | C44: 45923.26 | D44: Yes, I agree to voluntarily participate (thanks for your collaboration)! | E44: t7p6 | F44: No, I do not have a flood experience | G44: 1 | H44: Never | I44: 1 | J44: Once in the last six months | K44: 3 | L44: Never | M44: 1 | N44: Once in the last six months | O44: 3 | P44: Once in the last six months | Q44: 3 | R44: Never | S44: 1 | T44: Never | U44: 1 | V44: Very unlikely | W44: 1 | X44: A little increase | Y44: 2 | Z44: I won't get flooded | AA44: 1
A45: 44 | B45: True | C45: 45923.26 | D45: Yes, I agree to voluntarily participate (thanks for your collaboration)! | E45: t7p4 | F45: No, I do not have a flood experience | G45: 1 | H45: Once in the last year | I45: 2 | J45: Once a week | K45: 5 | L45: Once in the last year | M45: 2 | N45: Once in the last six months | O45: 3 | P45: Once in the last six months | Q45: 3 | R45: Never | S45: 1 | T45: Never | U45: 1 | V45: Likely | W45: 4 | X45: A big increase | Y45: 4 | Z45: I will suffer some damage | AA45: 4
A46: 45 | B46: True | C46: 45923.26 | D46: Yes, I agree to voluntarily participate (thanks for your collaboration)! | E46: t5p4 | F46: Yes, but without disruptions or damages | G46: 2 | H46: Never | I46: 1 | J46: Never | K46: 1 | L46: Never | M46: 1 | N46: Once in the last year | O46: 2 | P46: Once in the last year | Q46: 2 | R46: Never | S46: 1 | T46: Never | U46: 1 | V46: Unlikely | W46: 2 | X46: A moderate increase | Y46: 3 | Z46: If I get flooded, I won't get damaged | AA46: 2
... A53: 52 | B53: True | C53: 45923.263 | D53: Yes, I agree to voluntarily participate (thanks for your collaboration)! | E53: t5p6 | F53: Yes, with some disruptions or damages | G53: 4 | H53: Never | I53: 1 | J53: Once in the last six months | K53: 3 | L53: Never | M53: 1 | N53: Once in the last six months | O53: 3 | P53: Once in the last six months | Q53: 3 | R53: Never | S53: 1 | T53: Never | U53: 1 | V53: Likely | W53: 4 | X53: A big increase | Y53: 4 | Z53: I will suffer some damage | AA53: 4
F54: Response options
F55: =+Settings!$F$7 -> 1 = No, I do not have a flood experience | G55: =+COUNTIF(G$2:G$53,1) -> 35 | H55: =+Settings!$F$8 -> 1 = Never | I55: =+COUNTIF(I$2:I$53,1) -> 28 | J55: =+Settings!$F$8 -> 1 = Never | K55: =+COUNTIF(K$2:K$53,1) -> 12 | L55: =+Settings!$F$8 -> 1 = Never | M55: =+COUNTIF(M$2:M$53,1) -> 31 | N55: =+Settings!$F$8 -> 1 = Never | O55: =+COUNTIF(O$2:O$53,1) -> 6 | P55: =+Settings!$F$8 -> 1 = Never | Q55: =+COUNTIF(Q$2:Q$53,1) -> 12 | R55: =+Settings!$F$8 -> 1 = Never | S55: =+COUNTIF(S$2:S$53,1) -> 39 | T55: =+Settings!$F$8 -> 1 = Never | U55: =+COUNTIF(U$2:U$53,1) -> 45 | V55: =+Settings!$F$16 -> 1 = Very unlikely | W55: =+COUNTIF(W$2:W$53,1) -> 8 | X55: =+Settings!$F$17 -> 1 = No increase at all | Y55: =+COUNTIF(Y$2:Y$53,1) -> 0 | Z55: =+Settings!$F$18 -> 1 = I won't get flooded | AA55: =+COUNTIF(AA$2:AA$53,1) -> 4
F56: =+Settings!$G$7 -> 2 = Yes, but without disruptions or damages | G56: =+COUNTIF(G$2:G$53,2) -> 6 | H56: =+Settings!$G$8 -> 2 = Once in the last year | I56: =+COUNTIF(I$2:I$53,2) -> 12 | J56: =+Settings!$G$8 -> 2 = Once in the last year | K56: =+COUNTIF(K$2:K$53,2) -> 17 | L56: =+Settings!$G$8 -> 2 = Once in the last year | M56: =+COUNTIF(M$2:M$53,2) -> 9 | N56: =+Settings!$G$8 -> 2 = Once in the last year | O56: =+COUNTIF(O$2:O$53,2) -> 11 | P56: =+Settings!$G$8 -> 2 = Once in the last year | Q56: =+COUNTIF(Q$2:Q$53,2) -> 10 | R56: =+Settings!$G$8 -> 2 = Once in the last year | S56: =+COUNTIF(S$2:S$53,2) -> 6 | T56: =+Settings!$G$8 -> 2 = Once in the last year | U56: =+COUNTIF(U$2:U$53,2) -> 4 | V56: =+Settings!$G$16 -> 2 = Unlikely | W56: =+COUNTIF(W$2:W$53,2) -> 17 | X56: =+Settings!$G$17 -> 2 = A little increase | Y56: =+COUNTIF(Y$2:Y$53,2) -> 9 | Z56: =+Settings!$G$18 -> 2 = If I get flooded, I won't get damaged | AA56: =+COUNTIF(AA$2:AA$53,2) -> 9
F57: =+Settings!$H$7 -> 3 = Yes, with minor disruptions or damages | G57: =+COUNTIF(G$2:G$53,3) -> 5 | H57: =+Settings!$H$8 -> 3 = Once in the last six months | I57: =+COUNTIF(I$2:I$53,3) -> 7 | J57: =+Settings!$H$8 -> 3 = Once in the last six months | K57: =+COUNTIF(K$2:K$53,3) -> 11 | L57: =+Settings!$H$8 -> 3 = Once in the last six months | M57: =+COUNTIF(M$2:M$53,3) -> 7 | N57: =+Settings!$H$8 -> 3 = Once in the last six months | O57: =+COUNTIF(O$2:O$53,3) -> 20 | P57: =+Settings!$H$8 -> 3 = Once in the last six months | Q57: =+COUNTIF(Q$2:Q$53,3) -> 17 | R57: =+Settings!$H$8 -> 3 = Once in the last six months | S57: =+COUNTIF(S$2:S$53,3) -> 5 | T57: =+Settings!$H$8 -> 3 = Once in the last six months | U57: =+COUNTIF(U$2:U$53,3) -> 2 | V57: =+Settings!$H$16 -> 3 = Neutral | W57: =+COUNTIF(W$2:W$53,3) -> 9 | X57: =+Settings!$H$17 -> 3 = A moderate increase | Y57: =+COUNTIF(Y$2:Y$53,3) -> 11 | Z57: =+Settings!$H$18 -> 3 = I might suffer minor damage | AA57: =+COUNTIF(AA$2:AA$53,3) -> 22
F58: =+Settings!$I$7 -> 4 = Yes, with some disruptions or damages | G58: =+COUNTIF(G$2:G$53,4) -> 4 | H58: =+Settings!$I$8 -> 4 = Once a month | I58: =+COUNTIF(I$2:I$53,4) -> 4 | J58: =+Settings!$I$8 -> 4 = Once a month | K58: =+COUNTIF(K$2:K$53,4) -> 5 | L58: =+Settings!$I$8 -> 4 = Once a month | M58: =+COUNTIF(M$2:M$53,4) -> 4 | N58: =+Settings!$I$8 -> 4 = Once a month | O58: =+COUNTIF(O$2:O$53,4) -> 10 | P58: =+Settings!$I$8 -> 4 = Once a month | Q58: =+COUNTIF(Q$2:Q$53,4) -> 6 | R58: =+Settings!$I$8 -> 4 = Once a month | S58: =+COUNTIF(S$2:S$53,4) -> 0 | T58: =+Settings!$I$8 -> 4 = Once a month | U58: =+COUNTIF(U$2:U$53,4) -> 0 | V58: =+Settings!$I$16 -> 4 = Likely | W58: =+COUNTIF(W$2:W$53,4) -> 16 | X58: =+Settings!$I$17 -> 4 = A big increase | Y58: =+COUNTIF(Y$2:Y$53,4) -> 25 | Z58: =+Settings!$I$18 -> 4 = I will suffer some damage | AA58: =+COUNTIF(AA$2:AA$53,4) -> 12
F59: =+Settings!$J$7 -> 5 = Yes, with serious disruptions or damages | G59: =+COUNTIF(G$2:G$53,5) -> 1 | H59: =+Settings!$J$8 -> 5 = Once a week | I59: =+COUNTIF(I$2:I$53,5) -> 0 | J59: =+Settings!$J$8 -> 5 = Once a week | K59: =+COUNTIF(K$2:K$53,5) -> 3 | L59: =+Settings!$J$8 -> 5 = Once a week | M59: =+COUNTIF(M$2:M$53,5) -> 0 | N59: =+Settings!$J$8 -> 5 = Once a week | O59: =+COUNTIF(O$2:O$53,5) -> 3 | P59: =+Settings!$J$8 -> 5 = Once a week | Q59: =+COUNTIF(Q$2:Q$53,5) -> 2 | R59: =+Settings!$J$8 -> 5 = Once a week | S59: =+COUNTIF(S$2:S$53,5) -> 0 | T59: =+Settings!$J$8 -> 5 = Once a week | U59: =+COUNTIF(U$2:U$53,5) -> 0 | V59: =+Settings!$J$16 -> 5 = Very likely | W59: =+COUNTIF(W$2:W$53,5) -> 1 | X59: =+Settings!$J$17 -> 5 = An extreme increase | Y59: =+COUNTIF(Y$2:Y$53,5) -> 6 | Z59: =+Settings!$J$18 -> 5 = I will get seriously damaged | AA59: =+COUNTIF(AA$2:AA$53,5) -> 4
...

Sheet 240924
A1: id | B1: Q_SurveyFinished | C1: Q_RecordedDate | D1: Q_Consent | E1: Q_PlayerNumber | F1: Q_Experience | G1: Q_Experiencecode | H1: Q_Info_Government | I1: Q_Info_Governmentcode | J1: Q_Info_WeatherForecast | K1: Q_Info_WeatherForecastcode | L1: Q_Info_Scientific | M1: Q_Info_Scientificcode | N1: Q_Info_GeneralMedia | O1: Q_Info_GeneralMediacode | P1: Q_Info_SocialMedia | Q1: Q_Info_SocialMediacode | R1: Q_FloodFuture | S1: Q_FloodFuturecode | T1: Q_ClimateChange | U1: Q_ClimateChangecode | V1: Q_Threat | W1: Q_Threatcode
A2: 1 | B2: True | C2: 45559.1 | D2: Yes, I agree to voluntarily participate in this game session study (thanks for your collaboration)! | E2: t3p6 | F2: No, I do not have a flood experience | G2: 1 | H2: Never | I2: 1 | J2: Never | K2: 1 | L2: Never | M2: 1 | N2: Once in the last year | O2: 2 | P2: Never | Q2: 1 | R2: Very unlikely | S2: 1 | T2: A big increase | U2: 4 | V2: I won't get flooded | W2: 1
A3: 2 | B3: True | C3: 45559.101 | D3: Yes, I agree to voluntarily participate in this game session study (thanks for your collaboration)! | E3: t5p3 | F3: No, I do not have a flood experience | G3: 1 | H3: Once in the last year | I3: 2 | J3: Once a month | K3: 4 | L3: Once in the last year | M3: 2 | N3: Once a week | O3: 5 | P3: Once a month | Q3: 4 | R3: Unlikely | S3: 2 | T3: A moderate increase | U3: 3 | V3: I might suffer minor damage | W3: 3
A4: 3 | B4: True | C4: 45559.101 | D4: Yes, I agree to voluntarily participate in this game session study (thanks for your collaboration)! | E4: t4p6 | F4: No, I do not have a flood experience | G4: 1 | H4: Once in the last six months | I4: 3 | J4: Never | K4: 1 | L4: Once in the last six months | M4: 3 | N4: Once a month | O4: 4 | P4: Once a week | Q4: 5 | R4: Likely | S4: 4 | T4: An extreme increase | U4: 5 | V4: I will suffer some damage | W4: 4
A5: 4 | B5: True | C5: 45559.101 | D5: Yes, I agree to voluntarily participate in this game session study (thanks for your collaboration)! | E5: t2p6 | F5: No, I do not have a flood experience | G5: 1 | H5: Never | I5: 1 | J5: Never | K5: 1 | L5: Never | M5: 1 | N5: Once in the last six months | O5: 3 | P5: Once in the last year | Q5: 2 | R5: Very unlikely | S5: 1 | T5: A big increase | U5: 4 | V5: I might suffer minor damage | W5: 3
A6: 5 | B6: True | C6: 45559.102 | D6: Yes, I agree to voluntarily participate in this game session study (thanks for your collaboration)! | E6: t2p8 | F6: Yes, but without disruptions or damages | G6: 2 | H6: Never | I6: 1 | J6: Once in the last year | K6: 2 | L6: Never | M6: 1 | N6: Once in the last six months | O6: 3 | P6: Never | Q6: 1 | R6: Unlikely | S6: 2 | T6: A moderate increase | U6: 3 | V6: If I get flooded, I won't get damaged | W6: 2
A7: 6 | B7: True | C7: 45559.102 | D7: Yes, I agree to voluntarily participate in this game session study (thanks for your collaboration)! | E7: t4p8 | F7: No, I do not have a flood experience | G7: 1 | H7: Never | I7: 1 | J7: Never | K7: 1 | L7: Never | M7: 1 | N7: Once a month | O7: 4 | P7: Never | Q7: 1 | R7: Unlikely | S7: 2 | T7: An extreme increase | U7: 5 | V7: I will suffer some damage | W7: 4
A8: 7 | B8: True | C8: 45559.102 | D8: Yes, I agree to voluntarily participate in this game session study (thanks for your collaboration)! | E8: t3p4 | F8: No, I do not have a flood experience | G8: 1 | H8: Once in the last six months | I8: 3 | J8: Once in the last six months | K8: 3 | L8: Once in the last six months | M8: 3 | N8: Once a month | O8: 4 | P8: Once a month | Q8: 4 | R8: Neutral | S8: 3 | T8: A big increase | U8: 4 | V8: I might suffer minor damage | W8: 3
A9: 8 | B9: True | C9: 45559.102 | D9: Yes, I agree to voluntarily participate in this game session study (thanks for your collaboration)! | E9: t4p1 | F9: No, I do not have a flood experience | G9: 1 | H9: Once in the last year | I9: 2 | J9: Once in the last year | K9: 2 | L9: Never | M9: 1 | N9: Never | O9: 1 | P9: Once a month | Q9: 4 | R9: Unlikely | S9: 2 | T9: A moderate increase | U9: 3 | V9: I might suffer minor damage | W9: 3
A10: 9 | B10: True | C10: 45559.102 | D10: Yes, I agree to voluntarily participate in this game session study (thanks for your collaboration)! | E10: t4p2 | F10: No, I do not have a flood experience | G10: 1 | H10: Once in the last year | I10: 2 | J10: Never | K10: 1 | L10: Never | M10: 1 | N10: Once a month | O10: 4 | P10: Never | Q10: 1 | R10: Unlikely | S10: 2 | T10: A big increase | U10: 4 | V10: I might suffer minor damage | W10: 3
A11: 10 | B11: True | C11: 45559.102 | D11: Yes, I agree to voluntarily participate in this game session study (thanks for your collaboration)! | E11: t3p8 | F11: Yes, but without disruptions or damages | G11: 2 | H11: Never | I11: 1 | J11: Once a month | K11: 4 | L11: Never | M11: 1 | N11: Once a month | O11: 4 | P11: Once in the last six months | Q11: 3 | R11: Unlikely | S11: 2 | T11: A big increase | U11: 4 | V11: I might suffer minor damage | W11: 3
A12: 11 | B12: True | C12: 45559.102 | D12: Yes, I agree to voluntarily participate in this game session study (thanks for your collaboration)! | E12: t4p5 | F12: No, I do not have a flood experience | G12: 1 | H12: Never | I12: 1 | J12: Never | K12: 1 | L12: Never | M12: 1 | N12: Once in the last six months | O12: 3 | P12: Once in the last six months | Q12: 3 | R12: Unlikely | S12: 2 | T12: A big increase | U12: 4 | V12: I might suffer minor damage | W12: 3
A13: 12 | B13: True | C13: 45559.102 | D13: Yes, I agree to voluntarily participate in this game session study (thanks for your collaboration)! | E13: t2p2 | F13: Yes, but without disruptions or damages | G13: 2 | H13: Never | I13: 1 | J13: Never | K13: 1 | L13: Once in the last year | M13: 2 | N13: Once in the last six months | O13: 3 | P13: Once in the last six months | Q13: 3 | R13: Likely | S13: 4 | T13: A big increase | U13: 4 | V13: If I get flooded, I won't get damaged | W13: 2
... A79: 78 | B79: True | C79: 45559.266 | D79: Yes, I agree to voluntarily participate in this game session study (thanks for your collaboration)! | E79: t6p4 | F79: No, I do not have a flood experience | G79: 1 | H79: Never | I79: 1 | J79: Never | K79: 1 | L79: Never | M79: 1 | N79: Never | O79: 1 | P79: Never | Q79: 1 | R79: Unlikely | S79: 2 | T79: A moderate increase | U79: 3 | V79: I will suffer some damage | W79: 4
F80: Response options
F81: =+Settings!$F$7 -> 1 = No, I do not have a flood experience | G81: =+COUNTIF(G$2:G$79,1) -> 53 | H81: =+Settings!$F$8 -> 1 = Never | I81: =+COUNTIF(I$2:I$79,1) -> 39 | J81: =+Settings!$F$8 -> 1 = Never | K81: =+COUNTIF(K$2:K$79,1) -> 30 | L81: =+Settings!$F$8 -> 1 = Never | M81: =+COUNTIF(M$2:M$79,1) -> 47 | N81: =+Settings!$F$8 -> 1 = Never | O81: =+COUNTIF(O$2:O$79,1) -> 8 | P81: =+Settings!$F$8 -> 1 = Never | Q81: =+COUNTIF(Q$2:Q$79,1) -> 20 | R81: =+Settings!$F$16 -> 1 = Very unlikely | S81: =+COUNTIF(S$2:S$79,1) -> 13 | T81: =+Settings!$F$17 -> 1 = No increase at all | U81: =+COUNTIF(U$2:U$79,1) -> 1 | V81: =+Settings!$F$18 -> 1 = I won't get flooded | W81: =+COUNTIF(W$2:W$79,1) -> 14
F82: =+Settings!$G$7 -> 2 = Yes, but without disruptions or damages | G82: =+COUNTIF(G$2:G$79,2) -> 14 | H82: =+Settings!$G$8 -> 2 = Once in the last year | I82: =+COUNTIF(I$2:I$79,2) -> 20 | J82: =+Settings!$G$8 -> 2 = Once in the last year | K82: =+COUNTIF(K$2:K$79,2) -> 19 | L82: =+Settings!$G$8 -> 2 = Once in the last year | M82: =+COUNTIF(M$2:M$79,2) -> 16 | N82: =+Settings!$G$8 -> 2 = Once in the last year | O82: =+COUNTIF(O$2:O$79,2) -> 14 | P82: =+Settings!$G$8 -> 2 = Once in the last year | Q82: =+COUNTIF(Q$2:Q$79,2) -> 14 | R82: =+Settings!$G$16 -> 2 = Unlikely | S82: =+COUNTIF(S$2:S$79,2) -> 28 | T82: =+Settings!$G$17 -> 2 = A little increase | U82: =+COUNTIF(U$2:U$79,2) -> 15 | V82: =+Settings!$G$18 -> 2 = If I get flooded, I won't get damaged | W82: =+COUNTIF(W$2:W$79,2) -> 11
F83: =+Settings!$H$7 -> 3 = Yes, with minor disruptions or damages | G83: =+COUNTIF(G$2:G$79,3) -> 9 | H83: =+Settings!$H$8 -> 3 = Once in the last six months | I83: =+COUNTIF(I$2:I$79,3) -> 14 | J83: =+Settings!$H$8 -> 3 = Once in the last six months | K83: =+COUNTIF(K$2:K$79,3) -> 13 | L83: =+Settings!$H$8 -> 3 = Once in the last six months | M83: =+COUNTIF(M$2:M$79,3) -> 10 | N83: =+Settings!$H$8 -> 3 = Once in the last six months | O83: =+COUNTIF(O$2:O$79,3) -> 24 | P83: =+Settings!$H$8 -> 3 = Once in the last six months | Q83: =+COUNTIF(Q$2:Q$79,3) -> 17 | R83: =+Settings!$H$16 -> 3 = Neutral | S83: =+COUNTIF(S$2:S$79,3) -> 17 | T83: =+Settings!$H$17 -> 3 = A moderate increase | U83: =+COUNTIF(U$2:U$79,3) -> 17 | V83: =+Settings!$H$18 -> 3 = I might suffer minor damage | W83: =+COUNTIF(W$2:W$79,3) -> 34
F84: =+Settings!$I$7 -> 4 = Yes, with some disruptions or damages | G84: =+COUNTIF(G$2:G$79,4) -> 1 | H84: =+Settings!$I$8 -> 4 = Once a month | I84: =+COUNTIF(I$2:I$79,4) -> 5 | J84: =+Settings!$I$8 -> 4 = Once a month | K84: =+COUNTIF(K$2:K$79,4) -> 9 | L84: =+Settings!$I$8 -> 4 = Once a month | M84: =+COUNTIF(M$2:M$79,4) -> 4 | N84: =+Settings!$I$8 -> 4 = Once a month | O84: =+COUNTIF(O$2:O$79,4) -> 22 | P84: =+Settings!$I$8 -> 4 = Once a month | Q84: =+COUNTIF(Q$2:Q$79,4) -> 21 | R84: =+Settings!$I$16 -> 4 = Likely | S84: =+COUNTIF(S$2:S$79,4) -> 18 | T84: =+Settings!$I$17 -> 4 = A big increase | U84: =+COUNTIF(U$2:U$79,4) -> 34 | V84: =+Settings!$I$18 -> 4 = I will suffer some damage | W84: =+COUNTIF(W$2:W$79,4) -> 17
F85: =+Settings!$J$7 -> 5 = Yes, with serious disruptions or damages | G85: =+COUNTIF(G$2:G$79,5) -> 1 | H85: =+Settings!$J$8 -> 5 = Once a week | I85: =+COUNTIF(I$2:I$79,5) -> 0 | J85: =+Settings!$J$8 -> 5 = Once a week | K85: =+COUNTIF(K$2:K$79,5) -> 4 | L85: =+Settings!$J$8 -> 5 = Once a week | M85: =+COUNTIF(M$2:M$79,5) -> 1 | N85: =+Settings!$J$8 -> 5 = Once a week | O85: =+COUNTIF(O$2:O$79,5) -> 9 | P85: =+Settings!$J$8 -> 5 = Once a week | Q85: =+COUNTIF(Q$2:Q$79,5) -> 4 | R85: =+Settings!$J$16 -> 5 = Very likely | S85: =+COUNTIF(S$2:S$79,5) -> 2 | T85: =+Settings!$J$17 -> 5 = An extreme increase | U85: =+COUNTIF(U$2:U$79,5) -> 11 | V85: =+Settings!$J$18 -> 5 = I will get seriously damaged | W85: =+COUNTIF(W$2:W$79,5) -> 2
H86: =+Settings!$K$8 -> 6 = Once a day | I86: =+COUNTIF(I$2:I$79,6) -> 0 | J86: =+Settings!$K$8 -> 6 = Once a day | K86: =+COUNTIF(K$2:K$79,6) -> 3 | L86: =+Settings!$K$8 -> 6 = Once a day | M86: =+COUNTIF(M$2:M$79,6) -> 0 | N86: =+Settings!$K$8 -> 6 = Once a day | O86: =+COUNTIF(O$2:O$79,6) -> 1 | P86: =+Settings!$K$8 -> 6 = Once a day | Q86: =+COUNTIF(Q$2:Q$79,6) -> 2
F87: Mean | G87: {=+AVERAGE(VALUE(G$2:G$24))} -> 1.3913043 | H87: Mean | I87: {=+AVERAGE(VALUE(I$2:I$24))} -> 1.9130435 | J87: Mean | K87: {=+AVERAGE(VALUE(K$2:K$24))} -> 2.5652174 | L87: Mean | M87: {=+AVERAGE(VALUE(M$2:M$24))} -> 1.4782609 | N87: Mean | O87: {=+AVERAGE(VALUE(O$2:O$24))} -> 3.4347826 | P87: Mean | Q87: {=+AVERAGE(VALUE(Q$2:Q$24))} -> 2.9565217 | R87: Mean | S87: {=+AVERAGE(VALUE(S$2:S$24))} -> 2.4782609 | T87: Mean | U87: {=+AVERAGE(VALUE(U$2:U$24))} -> 3.826087 | V87: Mean | W87: {=+AVERAGE(VALUE(W$2:W$24))} -> 2.6956522
F88: Median | G88: {=+MEDIAN(VALUE(G$26:G$30))} -> 1 | H88: Median | I88: {=+MEDIAN(VALUE(I$26:I$30))} -> 2 | J88: Median | K88: {=+MEDIAN(VALUE(K$26:K$30))} -> 2 | L88: Median | M88: {=+MEDIAN(VALUE(M$26:M$30))} -> 1 | N88: Median | O88: {=+MEDIAN(VALUE(O$26:O$30))} -> 3 | P88: Median | Q88: {=+MEDIAN(VALUE(Q$26:Q$30))} -> 2 | R88: Median | S88: {=+MEDIAN(VALUE(S$26:S$30))} -> 2 | T88: Median | U88: {=+MEDIAN(VALUE(U$26:U$30))} -> 2 | V88: Median | W88: {=+MEDIAN(VALUE(W$26:W$30))} -> 2

Sheet Settings
A1: DataAnalysisQuestion | B1: QuestionAlias | C1: QuestionText | D1: QuestionColumn | E1: AnswerOptions | F1: Option1 | G1: Option2 | H1: Option3 | I1: Option4 | J1: Option5 | K1: Option6 | L1: Option7
A2: =+[1]Overview!A2 -> Presurvey_id-0-1 | B2: Q_SurveyFinished | C2: Finished | D2: 5 | E2: TRUE/FALSE
A3: =+[1]Overview!A3 -> Presurvey_id-0-2 | B3: Q_RecordedDate | C3: Recorded date | D3: 6 | E3: Date
A4: =+[1]Overview!A4 -> Presurvey_id-0-3 | B4: Q_Consent | C4: Do you agree to participate | D4: 10 | E4: Yes/No | F4: 2 = Yes, I agree to voluntarily participate (thanks for your collaboration)! | G4: 1 = No, I prefer not to participate (the survey ends, and you kindly wait for others to finish)
A5: =+[1]Overview!A5 -> Presurvey_id-0-4 | B5: Q_PlayerNumber | C5: Q1: Player number 1) Please fill in the table and player number (t#p#) you have been assigned | D5: 11 | E5: text
A6: =+[1]Overview!A8 -> 0 | B6: Q_Role_Faculty | C6: 3) What is your last or most relevant study program(s) about? | D6: 12 | E6: text
A7: =+[1]Overview!A10 -> RiskPerception_1 | B7: Q_Experience | C7: 4) Have you ever personally experienced any type of flood? (e.g. coastal, river or rain flood) | D7: 13 | E7: 5 | F7: 1 = No, I do not have a flood experience | G7: 2 = Yes, but without disruptions or damages | H7: 3 = Yes, with minor disruptions or damages | I7: 4 = Yes, with some disruptions or damages | J7: 5 = Yes, with serious disruptions or damages
A8: =+[1]Overview!A12 -> RiskPerception_2_1 | B8: Q_Info_Government | C8: Government (i.e. official letters, announcements etc.) | D8: 14 | E8: 6 | F8: 1 = Never | G8: 2 = Once in the last year | H8: 3 = Once in the last six months | I8: 4 = Once a month | J8: 5 = Once a week | K8: 6 = Once a day
A9: =+[1]Overview!A13 -> RiskPerception_2_2 | B9: Q_Info_WeatherForecast | C9: Weather forecast (i.e., flood warnings) | D9: 15 | E9: =+E$8 -> 6 | F9: =+F$8 -> 1 = Never | G9: =+G$8 -> 2 = Once in the last year | H9: =+H$8 -> 3 = Once in the last six months | I9: =+I$8 -> 4 = Once a month | J9: =+J$8 -> 5 = Once a week | K9: =+K$8 -> 6 = Once a day
A10: =+[1]Overview!A14 -> RiskPerception_2_3 | B10: Q_Info_Scientific | C10: Scientific (i.e. academic reports or publications) | D10: 16 | E10: =+E$8 -> 6 | F10: =+F$8 -> 1 = Never | G10: =+G$8 -> 2 = Once in the last year | H10: =+H$8 -> 3 = Once in the last six months | I10: =+I$8 -> 4 = Once a month | J10: =+J$8 -> 5 = Once a week | K10: =+K$8 -> 6 = Once a day
A11: =+[1]Overview!A15 -> RiskPerception_2_4 | B11: Q_Info_GeneralMedia | C11: General media (i.e. news, TV and radio) | D11: 17 | E11: =+E$8 -> 6 | F11: =+F$8 -> 1 = Never | G11: =+G$8 -> 2 = Once in the last year | H11: =+H$8 -> 3 = Once in the last six months | I11: =+I$8 -> 4 = Once a month | J11: =+J$8 -> 5 = Once a week | K11: =+K$8 -> 6 = Once a day
A12: =+[1]Overview!A16 -> RiskPerception_2_5 | B12: Q_Info_SocialMedia | C12: Social network or media (i,e, friends, family and colleagues) | D12: 18 | E12: =+E$8 -> 6 | F12: =+F$8 -> 1 = Never | G12: =+G$8 -> 2 = Once in the last year | H12: =+H$8 -> 3 = Once in the last six months | I12: =+I$8 -> 4 = Once a month | J12: =+J$8 -> 5 = Once a week | K12: =+K$8 -> 6 = Once a day
A13: =+[1]Overview!A17 -> RiskPerception_2_6 | B13: Q_Info_Engineering | C13: Engineering companies (i.e. flood-related measure brochures) | D13: 19 | E13: =+E$8 -> 6 | F13: =+F$8 -> 1 = Never | G13: =+G$8 -> 2 = Once in the last year | H13: =+H$8 -> 3 = Once in the last six months | I13: =+I$8 -> 4 = Once a month | J13: =+J$8 -> 5 = Once a week | K13: =+K$8 -> 6 = Once a day
A14: =+[1]Overview!A18 -> RiskPerception_2_7 | B14: Q_Info_Insurances | C14: Insurance companies (i.e. flood-related protection) | D14: 20 | E14: =+E$8 -> 6 | F14: =+F$8 -> 1 = Never | G14: =+G$8 -> 2 = Once in the last year | H14: =+H$8 -> 3 = Once in the last six months | I14: =+I$8 -> 4 = Once a month | J14: =+J$8 -> 5 = Once a week | K14: =+K$8 -> 6 = Once a day
A15: =+[1]Overview!A19 -> 0 | B15: Q_HouseLocation | C15: 6) In which country(ies) and cities have your house been for more than a year within the last five years? If many, specify maximum of three. | D15: 21 | E15: text
A16: =+[1]Overview!A20 -> RiskPerception_3 | B16: Q_FloodFuture | C16: 7) How likely do you consider any type of flood to happen to you in the next 5 to 10 years? | D16: 22 | E16: 5 | F16: 1 = Very unlikely | G16: 2 = Unlikely | H16: 3 = Neutral | I16: 4 = Likely | J16: 5 = Very likely
A17: =+[1]Overview!A21 -> RiskPerception_4 | B17: Q_ClimateChange | C17: 8) To what extent do you believe climate change will increase your likelihood or chance of being flooded in the next 5 to 10 years? | D17: 23 | E17: 5 | F17: 1 = No increase at all | G17: 2 = A little increase | H17: 3 = A moderate increase | I17: 4 = A big increase | J17: 5 = An extreme increase
A18: =+[1]Overview!A22 -> RiskPerception_5 | B18: Q_Threat | C18: 9) To what extent do you believe you will get damaged in the event of a major flood in the next 5 to 10 years? | D18: 24 | E18: 5 | F18: 1 = I won't get flooded | G18: 2 = If I get flooded, I won't get damaged | H18: 3 = I might suffer minor damage | I18: 4 = I will suffer some damage | J18: 5 = I will get seriously damaged

Sheet all
A1: Dataset | B1: id | C1: Q_SurveyFinished | D1: Q_RecordedDate | E1: Q_Consent | F1: Q_PlayerNumber | G1: Q_Experience | H1: Q_Experiencecode | I1: Q_Info_Government | J1: Q_Info_Governmentcode | K1: Q_Info_WeatherForecast | L1: Q_Info_WeatherForecastcode | M1: Q_Info_Scientific | N1: Q_Info_Scientificcode | O1: Q_Info_GeneralMedia | P1: Q_Info_GeneralMediacode | Q1: Q_Info_SocialMedia | R1: Q_Info_SocialMediacode | S1: Q_FloodFuture | T1: Q_FloodFuturecode | U1: Q_ClimateChange | V1: Q_ClimateChangecode | W1: Q_Threat | X1: Q_Threatcode
A2: 251007 | B2: =+'251007'!A2 -> 1 | C2: =+'251007'!B2 -> True | D2: =+'251007'!C2 -> 45937.248 | E2: =+'251007'!D2 -> 0 | F2: =+'251007'!E2 -> t3p3 | G2: =+'251007'!F2 -> Nee, ik heb G$een ervarinG$ met overstrominG$en | H2: =+'251007'!G2 -> 1 | I2: =+'251007'!H2 -> Eén keer in de afG$elopen zes maanden | ... R2: =+'251007'!Q2 -> 4 | S2: =+'251007'!V2 -> Neutraal | T2: =+'251007'!W2 -> 3 | U2: =+'251007'!X2 -> Een kleine toename | V2: =+'251007'!Y2 -> 2 | W2: =+'251007'!Z2 -> Ik zal eniG$e schade oplopen | X2: =+'251007'!AA2 -> 4
A3: 251007 | B3: =+'251007'!A3 -> 2 | C3: =+'251007'!B3 -> True | D3: =+'251007'!C3 -> 45937.251 | E3: =+'251007'!D3 -> Ja, ik G$a akkoord met vrijwilliG$e deelname (bedankt voor uw medewerkinG$)! | F3: =+'251007'!E3 -> t4p5 | G3: =+'251007'!F3 -> Nee, ik heb G$een ervarinG$ met overstrominG$en | H3: =+'251007'!G3 -> 1 | I3: =+'251007'!H3 -> Nooit | ... R3: =+'251007'!Q3 -> 3 | S3: =+'251007'!V3 -> Onwaarschijnlijk | T3: =+'251007'!W3 -> 2 | U3: =+'251007'!X3 -> Een kleine toename | V3: =+'251007'!Y3 -> 2 | W3: =+'251007'!Z3 -> G$een, Ik zal niet overstromen | X3: =+'251007'!AA3 -> 1
A4: 251007 | B4: =+'251007'!A4 -> 3 | C4: =+'251007'!B4 -> True | D4: =+'251007'!C4 -> 45937.251 | E4: =+'251007'!D4 -> Ja, ik G$a akkoord met vrijwilliG$e deelname (bedankt voor uw medewerkinG$)! | F4: =+'251007'!E4 -> t3p4 | G4: =+'251007'!F4 -> Nee, ik heb G$een ervarinG$ met overstrominG$en | H4: =+'251007'!G4 -> 1 | I4: =+'251007'!H4 -> Eén keer per week | ... R4: =+'251007'!Q4 -> 6 | S4: =+'251007'!V4 -> Neutraal | T4: =+'251007'!W4 -> 3 | U4: =+'251007'!X4 -> Een G$emiddelde toename | V4: =+'251007'!Y4 -> 3 | W4: =+'251007'!Z4 -> Ik zal eniG$e schade oplopen | X4: =+'251007'!AA4 -> 4
A5: 251007 | B5: =+'251007'!A5 -> 4 | C5: =+'251007'!B5 -> True | D5: =+'251007'!C5 -> 45937.251 | E5: =+'251007'!D5 -> Ja, ik G$a akkoord met vrijwilliG$e deelname (bedankt voor uw medewerkinG$)! | F5: =+'251007'!E5 -> t3p2 | G5: =+'251007'!F5 -> Ja, met eniG$e verstorinG$en of schade | H5: =+'251007'!G5 -> 4 | I5: =+'251007'!H5 -> Eén keer in het afG$elopen jaar | ... R5: =+'251007'!Q5 -> 2 | S5: =+'251007'!V5 -> Zeer onwaarschijnlijk | T5: =+'251007'!W5 -> 1 | U5: =+'251007'!X5 -> G$een toename | V5: =+'251007'!Y5 -> 1 | W5: =+'251007'!Z5 -> G$een, Ik zal niet overstromen | X5: =+'251007'!AA5 -> 1
A6: 251007 | B6: =+'251007'!A6 -> 5 | C6: =+'251007'!B6 -> True | D6: =+'251007'!C6 -> 45937.251 | E6: =+'251007'!D6 -> Ja, ik G$a akkoord met vrijwilliG$e deelname (bedankt voor uw medewerkinG$)! | F6: =+'251007'!E6 -> 3 en | G6: =+'251007'!F6 -> Nee, ik heb G$een ervarinG$ met overstrominG$en | H6: =+'251007'!G6 -> 1 | I6: =+'251007'!H6 -> Eén keer per maand | ... R6: =+'251007'!Q6 -> 5 | S6: =+'251007'!V6 -> Zeer onwaarschijnlijk | T6: =+'251007'!W6 -> 1 | U6: =+'251007'!X6 -> Een kleine toename | V6: =+'251007'!Y6 -> 2 | W6: =+'251007'!Z6 -> Als ik overstroom, zal ik G$een schade hebben | X6: =+'251007'!AA6 -> 2
A7: 251007 | B7: =+'251007'!A7 -> 6 | C7: =+'251007'!B7 -> True | D7: =+'251007'!C7 -> 45937.251 | E7: =+'251007'!D7 -> Ja, ik G$a akkoord met vrijwilliG$e deelname (bedankt voor uw medewerkinG$)! | F7: =+'251007'!E7 -> t2p4 | G7: =+'251007'!F7 -> Ja, met lichte verstorinG$en of schade | H7: =+'251007'!G7 -> 3 | I7: =+'251007'!H7 -> Nooit | ... R7: =+'251007'!Q7 -> 1 | S7: =+'251007'!V7 -> Waarschijnlijk | T7: =+'251007'!W7 -> 4 | U7: =+'251007'!X7 -> Een kleine toename | V7: =+'251007'!Y7 -> 2 | W7: =+'251007'!Z7 -> Ik zal eniG$e schade oplopen | X7: =+'251007'!AA7 -> 4
A8: 251007 | B8: =+'251007'!A8 -> 7 | C8: =+'251007'!B8 -> True | D8: =+'251007'!C8 -> 45937.251 | E8: =+'251007'!D8 -> Ja, ik G$a akkoord met vrijwilliG$e deelname (bedankt voor uw medewerkinG$)! | F8: =+'251007'!E8 -> t2p5 | G8: =+'251007'!F8 -> Ja, met eniG$e verstorinG$en of schade | H8: =+'251007'!G8 -> 4 | I8: =+'251007'!H8 -> Eén keer in het afG$elopen jaar | ... R8: =+'251007'!Q8 -> 3 | S8: =+'251007'!V8 -> Zeer onwaarschijnlijk | T8: =+'251007'!W8 -> 1 | U8: =+'251007'!X8 -> G$een toename | V8: =+'251007'!Y8 -> 1 | W8: =+'251007'!Z8 -> G$een, Ik zal niet overstromen | X8: =+'251007'!AA8 -> 1
A9: 251007 | B9: =+'251007'!A9 -> 8 | C9: =+'251007'!B9 -> True | D9: =+'251007'!C9 -> 45937.252 | E9: =+'251007'!D9 -> Ja, ik G$a akkoord met vrijwilliG$e deelname (bedankt voor uw medewerkinG$)! | F9: =+'251007'!E9 -> t4p6 | G9: =+'251007'!F9 -> Nee, ik heb G$een ervarinG$ met overstrominG$en | H9: =+'251007'!G9 -> 1 | I9: =+'251007'!H9 -> Eén keer in het afG$elopen jaar | ... R9: =+'251007'!Q9 -> 1 | S9: =+'251007'!V9 -> Onwaarschijnlijk | T9: =+'251007'!W9 -> 2 | U9: =+'251007'!X9 -> Een kleine toename | V9: =+'251007'!Y9 -> 2 | W9: =+'251007'!Z9 -> Ik zal eniG$e schade oplopen | X9: =+'251007'!AA9 -> 4
A10: 251007 | B10: =+'251007'!A10 -> 9 | C10: =+'251007'!B10 -> True | D10: =+'251007'!C10 -> 45937.252 | E10: =+'251007'!D10 -> Ja, ik G$a akkoord met vrijwilliG$e deelname (bedankt voor uw medewerkinG$)! | F10: =+'251007'!E10 -> t2p6 | G10: =+'251007'!F10 -> Ja, maar zonder verstorinG$en of schade | H10: =+'251007'!G10 -> 2 | I10: =+'251007'!H10 -> Nooit | ... R10: =+'251007'!Q10 -> 2 | S10: =+'251007'!V10 -> Zeer onwaarschijnlijk | T10: =+'251007'!W10 -> 1 | U10: =+'251007'!X10 -> Een kleine toename | V10: =+'251007'!Y10 -> 2 | W10: =+'251007'!Z10 -> Ik zou lichte schade kunnen oplopen | X10: =+'251007'!AA10 -> 3
A11: 251007 | B11: =+'251007'!A11 -> 10 | C11: =+'251007'!B11 -> True | D11: =+'251007'!C11 -> 45937.252 | E11: =+'251007'!D11 -> Ja, ik G$a akkoord met vrijwilliG$e deelname (bedankt voor uw medewerkinG$)! | F11: =+'251007'!E11 -> t4p4 | G11: =+'251007'!F11 -> Ja, met lichte verstorinG$en of schade | H11: =+'251007'!G11 -> 3 | I11: =+'251007'!H11 -> Eén keer in de afG$elopen zes maanden | ... R11: =+'251007'!Q11 -> 1 | S11: =+'251007'!V11 -> Waarschijnlijk | T11: =+'251007'!W11 -> 4 | U11: =+'251007'!X11 -> Een G$rote toename | V11: =+'251007'!Y11 -> 4 | W11: =+'251007'!Z11 -> Ik zou lichte schade kunnen oplopen | X11: =+'251007'!AA11 -> 3
A12: 251007 | B12: =+'251007'!A12 -> 11 | C12: =+'251007'!B12 -> True | D12: =+'251007'!C12 -> 45937.252 | E12: =+'251007'!D12 -> Ja, ik G$a akkoord met vrijwilliG$e deelname (bedankt voor uw medewerkinG$)! | F12: =+'251007'!E12 -> t3p5 | G12: =+'251007'!F12 -> Nee, ik heb G$een ervarinG$ met overstrominG$en | H12: =+'251007'!G12 -> 1 | I12: =+'251007'!H12 -> Eén keer in de afG$elopen zes maanden | ... R12: =+'251007'!Q12 -> 3 | S12: =+'251007'!V12 -> Zeer onwaarschijnlijk | T12: =+'251007'!W12 -> 1 | U12: =+'251007'!X12 -> G$een toename | V12: =+'251007'!Y12 -> 1 | W12: =+'251007'!Z12 -> G$een, Ik zal niet overstromen | X12: =+'251007'!AA12 -> 1
